<?xml version="1.0" encoding="utf-8"?>
<!-- This URDF was automatically created by SolidWorks to URDF Exporter! Originally created by Stephen Brawner (brawner@gmail.com) 
     Commit Version: 1.6.0-4-g7f85cfe  Build Version: 1.6.7995.38578
     For more information, please see http://wiki.ros.org/sw_urdf_exporter -->
<robot
  name="3RRR">
  <link
    name="Base">
    <inertial>
      <origin
        xyz="-6.605413806351E-16 -3.17888250122454E-15 0.00534836374604153"
        rpy="0 0 0" />
      <mass
        value="0.97649535402911" />
      <inertia
        ixx="0.0442557968886024"
        ixy="-1.60830380859908E-16"
        ixz="6.90467039096541E-18"
        iyy="0.0442557968886033"
        iyz="2.9961485964723E-17"
        izz="0.0884887523527264" />
    </inertial>
    <visual>
      <origin
        xyz="0 0 0"
        rpy="0 0 0" />
      <geometry>
        <mesh
          filename="package://3RRR/meshes/Base.STL" />
      </geometry>
      <material
        name="">
        <color
          rgba="1 0 1 1" />
      </material>
    </visual>
    <collision>
      <origin
        xyz="0 0 0"
        rpy="0 0 0" />
      <geometry>
        <mesh
          filename="package://3RRR/meshes/Base.STL" />
      </geometry>
    </collision>
  </link>
  <link
    name="Proximal_Link_1">
    <inertial>
      <origin
        xyz="0.125760356902669 -0.0328599019188576 -0.00566725132133209"
        rpy="0 0 0" />
      <mass
        value="0.124327488543993" />
      <inertia
        ixx="0.000103878846049437"
        ixy="0.000333488962144945"
        ixz="-1.04327876635405E-05"
        iyy="0.00129306029105497"
        iyz="2.72598025122248E-06"
        izz="0.0013933185659197" />
    </inertial>
    <visual>
      <origin
        xyz="0 0 0"
        rpy="0 0 0" />
      <geometry>
        <mesh
          filename="package://3RRR/meshes/Proximal_Link_1.STL" />
      </geometry>
      <material
        name="">
        <color
          rgba="0 1 1 1" />
      </material>
    </visual>
    <collision>
      <origin
        xyz="0 0 0"
        rpy="0 0 0" />
      <geometry>
        <mesh
          filename="package://3RRR/meshes/Proximal_Link_1.STL" />
      </geometry>
    </collision>
  </link>
  <joint
    name="Proximal_Joint_1"
    type="continuous">
    <origin
      xyz="-0.259807620025699 -0.149999987823395 0.03"
      rpy="0 0 0" />
    <parent
      link="Base" />
    <child
      link="Proximal_Link_1" />
    <axis
      xyz="0 0 1" />
  </joint>
  <link
    name="Distal_Link_1">
    <inertial>
      <origin
        xyz="-0.0284508779172917 0.102193979676703 -0.00575678198789127"
        rpy="0 0 0" />
      <mass
        value="0.109618995082061" />
      <inertia
        ixx="0.000804655386010645"
        ixy="0.000219736459397529"
        ixz="2.36021885468486E-06"
        iyy="7.65489682577738E-05"
        iyz="-8.47777556704603E-06"
        izz="0.000877843779154364" />
    </inertial>
    <visual>
      <origin
        xyz="0 0 0"
        rpy="0 0 0" />
      <geometry>
        <mesh
          filename="package://3RRR/meshes/Distal_Link_1.STL" />
      </geometry>
      <material
        name="">
        <color
          rgba="1 1 0 1" />
      </material>
    </visual>
    <collision>
      <origin
        xyz="0 0 0"
        rpy="0 0 0" />
      <geometry>
        <mesh
          filename="package://3RRR/meshes/Distal_Link_1.STL" />
      </geometry>
    </collision>
  </link>
  <joint
    name="Distal_Joint_1"
    type="continuous">
    <origin
      xyz="0.290255371031986 -0.0758407594233355 0.00999999999999951"
      rpy="0 0 0" />
    <parent
      link="Proximal_Link_1" />
    <child
      link="Distal_Link_1" />
    <axis
      xyz="0 0 1" />
  </joint>
  <link
    name="Platform_1">
    <inertial>
      <origin
        xyz="0.0866025100946127 0.0499999825156258 -0.00621550806782306"
        rpy="0 0 0" />
      <mass
        value="0.204748162200477" />
      <inertia
        ixx="0.000566208682172371"
        ixy="-1.23947503241835E-17"
        ixz="-2.7619049018082E-19"
        iyy="0.000566208682172315"
        iyz="4.71492949155226E-18"
        izz="0.00112463244849747" />
    </inertial>
    <visual>
      <origin
        xyz="0 0 0"
        rpy="0 0 0" />
      <geometry>
        <mesh
          filename="package://3RRR/meshes/Platform_1.STL" />
      </geometry>
      <material
        name="">
        <color
          rgba="1 0 0 1" />
      </material>
    </visual>
    <collision>
      <origin
        xyz="0 0 0"
        rpy="0 0 0" />
      <geometry>
        <mesh
          filename="package://3RRR/meshes/Platform_1.STL" />
      </geometry>
    </collision>
  </link>
  <joint
    name="Platform_Joint_1"
    type="continuous">
    <origin
      xyz="-0.0670502383712165 0.24084074724673 0.0100000000000002"
      rpy="0 0 0" />
    <parent
      link="Distal_Link_1" />
    <child
      link="Platform_1" />
    <axis
      xyz="0 0 -1" />
  </joint>
  <link
    name="Pen_1">
    <inertial>
      <origin
        xyz="4.85722573273506E-17 -1.38777878078145E-17 0.0282692307692308"
        rpy="0 0 0" />
      <mass
        value="0.00340339204138894" />
      <inertia
        ixx="5.62818337732057E-07"
        ixy="-3.62721401838554E-24"
        ixz="-8.1668323214017E-22"
        iyy="5.62818337732057E-07"
        iyz="1.63847144627279E-22"
        izz="4.12334035783661E-08" />
    </inertial>
    <visual>
      <origin
        xyz="0 0 0"
        rpy="0 0 0" />
      <geometry>
        <mesh
          filename="package://3RRR/meshes/Pen_1.STL" />
      </geometry>
      <material
        name="">
        <color
          rgba="0 0 1 1" />
      </material>
    </visual>
    <collision>
      <origin
        xyz="0 0 0"
        rpy="0 0 0" />
      <geometry>
        <mesh
          filename="package://3RRR/meshes/Pen_1.STL" />
      </geometry>
    </collision>
  </link>
  <joint
    name="Pen_Joint_1"
    type="fixed">
    <origin
      xyz="0.0866025100946131 0.0499999825156236 -0.0500000000000001"
      rpy="0 0 0" />
    <parent
      link="Platform_1" />
    <child
      link="Pen_1" />
    <axis
      xyz="0 0 0" />
  </joint>
  <link
    name="Proximal_Link_2">
    <inertial>
      <origin
        xyz="0.0418779305079323 0.123051524422847 -0.00566725132133179"
        rpy="0 0 0" />
      <mass
        value="0.124327488543994" />
      <inertia
        ixx="0.00123866971628232"
        ixy="-0.000415856724787782"
        ixz="-3.47409512336009E-06"
        iyy="0.000158269420822236"
        iyz="-1.02080698389299E-05"
        izz="0.00139331856591985" />
    </inertial>
    <visual>
      <origin
        xyz="0 0 0"
        rpy="0 0 0" />
      <geometry>
        <mesh
          filename="package://3RRR/meshes/Proximal_Link_2.STL" />
      </geometry>
      <material
        name="">
        <color
          rgba="0 1 1 1" />
      </material>
    </visual>
    <collision>
      <origin
        xyz="0 0 0"
        rpy="0 0 0" />
      <geometry>
        <mesh
          filename="package://3RRR/meshes/Proximal_Link_2.STL" />
      </geometry>
    </collision>
  </link>
  <joint
    name="Proximal_Joint_2"
    type="continuous">
    <origin
      xyz="0.259807610563355 -0.149999991221948 0.0299999999999999"
      rpy="0 0 0" />
    <parent
      link="Base" />
    <child
      link="Proximal_Link_2" />
    <axis
      xyz="0 0 1" />
  </joint>
  <link
    name="Distal_Link_2">
    <inertial>
      <origin
        xyz="-0.0932911716913216 -0.0504957346801424 -0.00575678198789124"
        rpy="0 0 0" />
      <mass
        value="0.109618995082061" />
      <inertia
        ixx="0.000208078089939355"
        ixy="-0.000356021627652015"
        ixz="7.73921926211201E-06"
        iyy="0.000673126264329077"
        iyz="4.18900904990346E-06"
        izz="0.000877843779154377" />
    </inertial>
    <visual>
      <origin
        xyz="0 0 0"
        rpy="0 0 0" />
      <geometry>
        <mesh
          filename="package://3RRR/meshes/Distal_Link_2.STL" />
      </geometry>
      <material
        name="">
        <color
          rgba="1 1 0 1" />
      </material>
    </visual>
    <collision>
      <origin
        xyz="0 0 0"
        rpy="0 0 0" />
      <geometry>
        <mesh
          filename="package://3RRR/meshes/Distal_Link_2.STL" />
      </geometry>
    </collision>
  </link>
  <joint
    name="Distal_Joint_2"
    type="continuous">
    <origin
      xyz="0.0966544049109075 0.284003385664662 0.0100000000000001"
      rpy="0 0 0" />
    <parent
      link="Proximal_Link_2" />
    <child
      link="Distal_Link_2" />
    <axis
      xyz="0 0 1" />
  </joint>
  <link
    name="Platform_2">
    <inertial>
      <origin
        xyz="-0.0866025100946149 0.0499999825156237 -0.00621550806782279"
        rpy="0 0 0" />
      <mass
        value="0.204748162200477" />
      <inertia
        ixx="0.000566208682172371"
        ixy="-1.2403409707052E-17"
        ixz="-2.76974763643588E-19"
        iyy="0.000566208682172315"
        iyz="4.72154693645268E-18"
        izz="0.00112463244849747" />
    </inertial>
    <visual>
      <origin
        xyz="0 0 0"
        rpy="0 0 0" />
      <geometry>
        <mesh
          filename="package://3RRR/meshes/Platform_2.STL" />
      </geometry>
      <material
        name="">
        <color
          rgba="1 0 0 1" />
      </material>
    </visual>
    <collision>
      <origin
        xyz="0 0 0"
        rpy="0 0 0" />
      <geometry>
        <mesh
          filename="package://3RRR/meshes/Platform_2.STL" />
      </geometry>
    </collision>
  </link>
  <joint
    name="Platform_Joint_2"
    type="continuous">
    <origin
      xyz="-0.219859482649965 -0.119003394442713 0.00999999999999951"
      rpy="0 0 0" />
    <parent
      link="Distal_Link_2" />
    <child
      link="Platform_2" />
    <axis
      xyz="0 0 -1" />
  </joint>
  <link
    name="Pen_2">
    <inertial>
      <origin
        xyz="4.85722573273506E-17 -1.38777878078145E-17 0.0282692307692308"
        rpy="0 0 0" />
      <mass
        value="0.00340339204138894" />
      <inertia
        ixx="5.62818337732057E-07"
        ixy="-3.62721401838554E-24"
        ixz="-8.1668323214017E-22"
        iyy="5.62818337732057E-07"
        iyz="1.63847144627279E-22"
        izz="4.12334035783661E-08" />
    </inertial>
    <visual>
      <origin
        xyz="0 0 0"
        rpy="0 0 0" />
      <geometry>
        <mesh
          filename="package://3RRR/meshes/Pen_2.STL" />
      </geometry>
      <material
        name="">
        <color
          rgba="0 0 1 1" />
      </material>
    </visual>
    <collision>
      <origin
        xyz="0 0 0"
        rpy="0 0 0" />
      <geometry>
        <mesh
          filename="package://3RRR/meshes/Pen_2.STL" />
      </geometry>
    </collision>
  </link>
  <joint
    name="Pen_Joint_2"
    type="fixed">
    <origin
      xyz="-0.0866025100946145 0.0499999825156215 -0.0499999999999999"
      rpy="0 0 0" />
    <parent
      link="Platform_2" />
    <child
      link="Pen_2" />
    <axis
      xyz="0 0 0" />
  </joint>
  <link
    name="Proximal_Link_3">
    <inertial>
      <origin
        xyz="-0.0759200738592423 -0.10550624440741 -0.00566725132133162"
        rpy="0 0 0" />
      <mass
        value="0.124327488543993" />
      <inertia
        ixx="0.000915055567953722"
        ixy="-0.000646408168282344"
        ixz="6.29815820413009E-06"
        iyy="0.000481883569150672"
        iyz="8.75255562669496E-06"
        izz="0.00139331856591969" />
    </inertial>
    <visual>
      <origin
        xyz="0 0 0"
        rpy="0 0 0" />
      <geometry>
        <mesh
          filename="package://3RRR/meshes/Proximal_Link_3.STL" />
      </geometry>
      <material
        name="">
        <color
          rgba="0 1 1 1" />
      </material>
    </visual>
    <collision>
      <origin
        xyz="0 0 0"
        rpy="0 0 0" />
      <geometry>
        <mesh
          filename="package://3RRR/meshes/Proximal_Link_3.STL" />
      </geometry>
    </collision>
  </link>
  <joint
    name="Proximal_Joint_3"
    type="continuous">
    <origin
      xyz="0 0.29999997277284 0.0299999999999998"
      rpy="0 0 0" />
    <parent
      link="Base" />
    <child
      link="Proximal_Link_3" />
    <axis
      xyz="0 0 1" />
  </joint>
  <link
    name="Distal_Link_3">
    <inertial>
      <origin
        xyz="0.0955674413545898 0.0460426551076721 -0.00575678198789149"
        rpy="0 0 0" />
      <mass
        value="0.109618995082061" />
      <inertia
        ixx="0.000175588693399224"
        ixy="-0.000332545792215708"
        ixz="-7.92805331472561E-06"
        iyy="0.000705615660869294"
        iyz="-3.81959189522254E-06"
        izz="0.000877843779154462" />
    </inertial>
    <visual>
      <origin
        xyz="0 0 0"
        rpy="0 0 0" />
      <geometry>
        <mesh
          filename="package://3RRR/meshes/Distal_Link_3.STL" />
      </geometry>
      <material
        name="">
        <color
          rgba="1 1 0 1" />
      </material>
    </visual>
    <collision>
      <origin
        xyz="0 0 0"
        rpy="0 0 0" />
      <geometry>
        <mesh
          filename="package://3RRR/meshes/Distal_Link_3.STL" />
      </geometry>
    </collision>
  </link>
  <joint
    name="Distal_Joint_3"
    type="continuous">
    <origin
      xyz="-0.175223889501665 -0.243508838528245 0.0100000000000004"
      rpy="0 0 0" />
    <parent
      link="Proximal_Link_3" />
    <child
      link="Distal_Link_3" />
    <axis
      xyz="0 0 1" />
  </joint>
  <link
    name="Platform_3">
    <inertial>
      <origin
        xyz="-4.78783679369599E-16 -0.0999999650312424 -0.00621550806782298"
        rpy="0 0 0" />
      <mass
        value="0.204748162200477" />
      <inertia
        ixx="0.00056620868217237"
        ixy="-1.24093500608381E-17"
        ixz="-2.74753632241765E-19"
        iyy="0.000566208682172315"
        iyz="4.71823821400247E-18"
        izz="0.00112463244849747" />
    </inertial>
    <visual>
      <origin
        xyz="0 0 0"
        rpy="0 0 0" />
      <geometry>
        <mesh
          filename="package://3RRR/meshes/Platform_3.STL" />
      </geometry>
      <material
        name="">
        <color
          rgba="1 0 0 1" />
      </material>
    </visual>
    <collision>
      <origin
        xyz="0 0 0"
        rpy="0 0 0" />
      <geometry>
        <mesh
          filename="package://3RRR/meshes/Platform_3.STL" />
      </geometry>
    </collision>
  </link>
  <joint
    name="Platform_Joint_3"
    type="continuous">
    <origin
      xyz="0.225223971716447 0.108508813302272 0.00999999999999947"
      rpy="0 0 0" />
    <parent
      link="Distal_Link_3" />
    <child
      link="Platform_3" />
    <axis
      xyz="0 0 -1" />
  </joint>
  <link
    name="Pen_3">
    <inertial>
      <origin
        xyz="4.85722573273506E-17 -1.38777878078145E-17 0.0282692307692308"
        rpy="0 0 0" />
      <mass
        value="0.00340339204138894" />
      <inertia
        ixx="5.62818337732057E-07"
        ixy="-3.62721401838554E-24"
        ixz="-8.1668323214017E-22"
        iyy="5.62818337732057E-07"
        iyz="1.63847144627279E-22"
        izz="4.12334035783661E-08" />
    </inertial>
    <visual>
      <origin
        xyz="0 0 0"
        rpy="0 0 0" />
      <geometry>
        <mesh
          filename="package://3RRR/meshes/Pen_3.STL" />
      </geometry>
      <material
        name="">
        <color
          rgba="0 0 1 1" />
      </material>
    </visual>
    <collision>
      <origin
        xyz="0 0 0"
        rpy="0 0 0" />
      <geometry>
        <mesh
          filename="package://3RRR/meshes/Pen_3.STL" />
      </geometry>
    </collision>
  </link>
  <joint
    name="Pen_Joint_3"
    type="fixed">
    <origin
      xyz="0 -0.0999999650312446 -0.05"
      rpy="0 0 0" />
    <parent
      link="Platform_3" />
    <child
      link="Pen_3" />
    <axis
      xyz="0 0 0" />
  </joint>
</robot>