<?xml version="1.0" encoding="utf-8"?>
<!-- This URDF was automatically created by SolidWorks to URDF Exporter! Originally created by Stephen Brawner (brawner@gmail.com) 
     Commit Version: 1.6.0-4-g7f85cfe  Build Version: 1.6.7995.38578
     For more information, please see http://wiki.ros.org/sw_urdf_exporter -->
<robot
  name="Mobile Manipulator Robot">
  <link
    name="Mobile_Base">
    <inertial>
      <origin
        xyz="-6.97391474819404E-18 -0.224989222646701 1.37375505420621E-17"
        rpy="0 0 0" />
      <mass
        value="389.392145867644" />
      <inertia
        ixx="32.4757754116668"
        ixy="6.09571601276593E-17"
        ixz="-4.43542421848178E-16"
        iyy="61.8336865920494"
        iyz="-2.119974048337E-15"
        izz="42.4014331686187" />
    </inertial>
    <visual>
      <origin
        xyz="0 0 0"
        rpy="0 0 0" />
      <geometry>
        <mesh
          filename="package://Mobile Manipulator Robot/meshes/Mobile_Base.STL" />
      </geometry>
      <material
        name="">
        <color
          rgba="1 0 0 1" />
      </material>
    </visual>
    <collision>
      <origin
        xyz="0 0 0"
        rpy="0 0 0" />
      <geometry>
        <mesh
          filename="package://Mobile Manipulator Robot/meshes/Mobile_Base.STL" />
      </geometry>
    </collision>
  </link>
  <link
    name="Left_Wheel">
    <inertial>
      <origin
        xyz="0.101054925558571 -5.58616460550371E-18 -5.55111512312578E-17"
        rpy="0 0 0" />
      <mass
        value="37.2252884109526" />
      <inertia
        ixx="1.15060342056414"
        ixy="-1.80206563927507E-18"
        ixz="8.19785431691663E-18"
        iyy="0.699344578155435"
        iyz="1.95585201476938E-16"
        izz="0.699344578155434" />
    </inertial>
    <visual>
      <origin
        xyz="0 0 0"
        rpy="0 0 0" />
      <geometry>
        <mesh
          filename="package://Mobile Manipulator Robot/meshes/Left_Wheel.STL" />
      </geometry>
      <material
        name="">
        <color
          rgba="0.250980392156863 0.250980392156863 0.250980392156863 1" />
      </material>
    </visual>
    <collision>
      <origin
        xyz="0 0 0"
        rpy="0 0 0" />
      <geometry>
        <mesh
          filename="package://Mobile Manipulator Robot/meshes/Left_Wheel.STL" />
      </geometry>
    </collision>
  </link>
  <joint
    name="Left_Wheel"
    type="continuous">
    <origin
      xyz="0 -0.19 0.4"
      rpy="1.5707963267949 -1.5707963267949 0" />
    <parent
      link="Mobile_Base" />
    <child
      link="Left_Wheel" />
    <axis
      xyz="1 0 0" />
  </joint>
  <link
    name="Right_Wheel">
    <inertial>
      <origin
        xyz="0.101054925558571 3.50055370159164E-16 -2.77555756156289E-17"
        rpy="0 0 0" />
      <mass
        value="37.2252884109526" />
      <inertia
        ixx="1.15060342056414"
        ixy="1.5769963060077E-15"
        ixz="-8.12324233204896E-18"
        iyy="0.699344578155435"
        iyz="1.90053017540184E-16"
        izz="0.699344578155434" />
    </inertial>
    <visual>
      <origin
        xyz="0 0 0"
        rpy="0 0 0" />
      <geometry>
        <mesh
          filename="package://Mobile Manipulator Robot/meshes/Right_Wheel.STL" />
      </geometry>
      <material
        name="">
        <color
          rgba="0.250980392156863 0.250980392156863 0.250980392156863 1" />
      </material>
    </visual>
    <collision>
      <origin
        xyz="0 0 0"
        rpy="0 0 0" />
      <geometry>
        <mesh
          filename="package://Mobile Manipulator Robot/meshes/Right_Wheel.STL" />
      </geometry>
    </collision>
  </link>
  <joint
    name="Right_Wheel"
    type="continuous">
    <origin
      xyz="0 -0.19 -0.4"
      rpy="1.5707963267949 1.5707963267949 0" />
    <parent
      link="Mobile_Base" />
    <child
      link="Right_Wheel" />
    <axis
      xyz="1 0 0" />
  </joint>
  <link
    name="Proximal_Link">
    <inertial>
      <origin
        xyz="1.20104170376266 1.45382314335634E-13 0.0120104170376265"
        rpy="0 0 0" />
      <mass
        value="10.0263671297658" />
      <inertia
        ixx="0.0207386316690575"
        ixy="-7.02605432165205E-14"
        ixz="-0.00589559967686835"
        iyy="6.78083329533579"
        iyz="-4.08250625099012E-16"
        izz="6.8002868833056" />
    </inertial>
    <visual>
      <origin
        xyz="0 0 0"
        rpy="0 0 0" />
      <geometry>
        <mesh
          filename="package://Mobile Manipulator Robot/meshes/Proximal_Link.STL" />
      </geometry>
      <material
        name="">
        <color
          rgba="0 1 1 1" />
      </material>
    </visual>
    <collision>
      <origin
        xyz="0 0 0"
        rpy="0 0 0" />
      <geometry>
        <mesh
          filename="package://Mobile Manipulator Robot/meshes/Proximal_Link.STL" />
      </geometry>
    </collision>
  </link>
  <joint
    name="Proximal_Link_Joint"
    type="continuous">
    <origin
      xyz="0 -0.45 0"
      rpy="1.5707963267949 0 0" />
    <parent
      link="Mobile_Base" />
    <child
      link="Proximal_Link" />
    <axis
      xyz="0 0 1" />
  </joint>
  <link
    name="Distal_Link">
    <inertial>
      <origin
        xyz="0.474884012233657 -3.25648816660227E-16 0.0135046395106537"
        rpy="0 0 0" />
      <mass
        value="4.88606954950425" />
      <inertia
        ixx="0.0110436552930567"
        ixy="4.82724614818732E-14"
        ixz="0.00233108144396956"
        iyy="0.630157043467138"
        iyz="-2.26631039976967E-17"
        izz="0.640456159281391" />
    </inertial>
    <visual>
      <origin
        xyz="0 0 0"
        rpy="0 0 0" />
      <geometry>
        <mesh
          filename="package://Mobile Manipulator Robot/meshes/Distal_Link.STL" />
      </geometry>
      <material
        name="">
        <color
          rgba="1 1 0 1" />
      </material>
    </visual>
    <collision>
      <origin
        xyz="0 0 0"
        rpy="0 0 0" />
      <geometry>
        <mesh
          filename="package://Mobile Manipulator Robot/meshes/Distal_Link.STL" />
      </geometry>
    </collision>
  </link>
  <joint
    name="Distal_Link_Joint"
    type="continuous">
    <origin
      xyz="2.5 0 -0.0249999999999996"
      rpy="0 0 0" />
    <parent
      link="Proximal_Link" />
    <child
      link="Distal_Link" />
    <axis
      xyz="0 0 -1" />
  </joint>
  <link
    name="Pen">
    <inertial>
      <origin
        xyz="-4.44089209850063E-16 -3.81454348360146E-17 -0.233482142857143"
        rpy="0 0 0" />
      <mass
        value="0.916297857297023" />
      <inertia
        ixx="0.0168344530165384"
        ixy="-1.05879118406787E-20"
        ixz="-2.22099145379937E-19"
        iyy="0.0168344530165384"
        iyz="5.08354191049358E-18"
        izz="0.000282252464970958" />
    </inertial>
    <visual>
      <origin
        xyz="0 0 0"
        rpy="0 0 0" />
      <geometry>
        <mesh
          filename="package://Mobile Manipulator Robot/meshes/Pen.STL" />
      </geometry>
      <material
        name="">
        <color
          rgba="0 0 1 1" />
      </material>
    </visual>
    <collision>
      <origin
        xyz="0 0 0"
        rpy="0 0 0" />
      <geometry>
        <mesh
          filename="package://Mobile Manipulator Robot/meshes/Pen.STL" />
      </geometry>
    </collision>
  </link>
  <joint
    name="Pen"
    type="fixed">
    <origin
      xyz="0.999999999999999 0 0.0249999999999996"
      rpy="0 0 0" />
    <parent
      link="Distal_Link" />
    <child
      link="Pen" />
    <axis
      xyz="0 0 0" />
  </joint>
  <link
    name="Front_Support">
    <inertial>
      <origin
        xyz="-2.77555756156289E-16 -6.35003179048233E-17 -0.0224501330709969"
        rpy="0 0 0" />
      <mass
        value="0.419720208644154" />
      <inertia
        ixx="0.000403252529175268"
        ixy="-2.04565792547015E-20"
        ixz="1.50841124694842E-18"
        iyy="0.000403252529175268"
        iyz="-6.69991697038779E-21"
        izz="0.000613969677091575" />
    </inertial>
    <visual>
      <origin
        xyz="0 0 0"
        rpy="0 0 0" />
      <geometry>
        <mesh
          filename="package://Mobile Manipulator Robot/meshes/Front_Support.STL" />
      </geometry>
      <material
        name="">
        <color
          rgba="0.250980392156863 0.250980392156863 0.250980392156863 1" />
      </material>
    </visual>
    <collision>
      <origin
        xyz="0 0 0"
        rpy="0 0 0" />
      <geometry>
        <mesh
          filename="package://Mobile Manipulator Robot/meshes/Front_Support.STL" />
      </geometry>
    </collision>
  </link>
  <joint
    name="Front_Support"
    type="fixed">
    <origin
      xyz="0.35 -0.0249999999999976 0"
      rpy="1.5707963267949 0 0" />
    <parent
      link="Mobile_Base" />
    <child
      link="Front_Support" />
    <axis
      xyz="0 0 0" />
  </joint>
  <link
    name="Rear_Support">
    <inertial>
      <origin
        xyz="-1.11022302462516E-16 3.36441967498779E-17 -0.0224501330709969"
        rpy="0 0 0" />
      <mass
        value="0.419720208644154" />
      <inertia
        ixx="0.000403252529175268"
        ixy="-2.04565792547015E-20"
        ixz="1.50841124694842E-18"
        iyy="0.000403252529175268"
        iyz="-6.69991697038779E-21"
        izz="0.000613969677091575" />
    </inertial>
    <visual>
      <origin
        xyz="0 0 0"
        rpy="0 0 0" />
      <geometry>
        <mesh
          filename="package://Mobile Manipulator Robot/meshes/Rear_Support.STL" />
      </geometry>
      <material
        name="">
        <color
          rgba="0.250980392156863 0.250980392156863 0.250980392156863 1" />
      </material>
    </visual>
    <collision>
      <origin
        xyz="0 0 0"
        rpy="0 0 0" />
      <geometry>
        <mesh
          filename="package://Mobile Manipulator Robot/meshes/Rear_Support.STL" />
      </geometry>
    </collision>
  </link>
  <joint
    name="Rear_Support"
    type="fixed">
    <origin
      xyz="-0.35 -0.0250000000000024 0"
      rpy="1.5707963267949 0 0" />
    <parent
      link="Mobile_Base" />
    <child
      link="Rear_Support" />
    <axis
      xyz="0 0 0" />
  </joint>
</robot>